Traceback (most recent call last):
  File "/users/acc22xl/llama_adversarial_classification/scripts/classify_adversarial.py", line 194, in <module>
    main()
  File "/users/acc22xl/llama_adversarial_classification/scripts/classify_adversarial.py", line 165, in main
    df = load_data('./data/adversarial_dataset.csv')
  File "/users/acc22xl/llama_adversarial_classification/scripts/classify_adversarial.py", line 10, in load_data
    df = pd.read_csv(file_path)
  File "/users/acc22xl/.local/lib/python3.10/site-packages/pandas/io/parsers/readers.py", line 1026, in read_csv
    return _read(filepath_or_buffer, kwds)
  File "/users/acc22xl/.local/lib/python3.10/site-packages/pandas/io/parsers/readers.py", line 620, in _read
    parser = TextFileReader(filepath_or_buffer, **kwds)
  File "/users/acc22xl/.local/lib/python3.10/site-packages/pandas/io/parsers/readers.py", line 1620, in __init__
    self._engine = self._make_engine(f, self.engine)
  File "/users/acc22xl/.local/lib/python3.10/site-packages/pandas/io/parsers/readers.py", line 1880, in _make_engine
    self.handles = get_handle(
  File "/users/acc22xl/.local/lib/python3.10/site-packages/pandas/io/common.py", line 873, in get_handle
    handle = open(
FileNotFoundError: [Errno 2] No such file or directory: './data/adversarial_dataset.csv'
